Workbook

Sheet Positions
A1: Positions extract -- run this against the warehouse, paste below
A3: SELECT
A4: p.client_code,
A5: p.client_name,
A6: p.as_of_date,
A7: p.period_month,
A8: p.mandate,
A9: p.market_value_gbp
A10: FROM fin.positions p
A11: JOIN fin.mandates m
A12: ON m.client_code = p.client_code
A13: WHERE p.period_month IN ('2026-10', '2026-11')
... A15: ORDER BY p.client_code, p.as_of_date
A17: client_code | B17: client_name | C17: as_of_date | D17: period_month | E17: mandate | F17: market_value_gbp
A18: 00001 | B18: Client 001 Holdings | C18: 46323 | D18: 2026-10 | E18: balanced | F18: 8277234.3
A19: 00001 | B19: Client 001 Holdings | C19: 46354 | D19: 2026-11 | E19: balanced | F19: 14800746
A20: 00002 | B20: Client 002 Holdings | C20: 46323 | D20: 2026-10 | E20: equity | F20: 17676688
A21: 00002 | B21: Client 002 Holdings | C21: 46354 | D21: 2026-11 | E21: equity | F21: 89021933
A22: 00003 | B22: Client 003 Holdings | C22: 46323 | D22: 2026-10 | E22: fixed income | F22: 73487515
A23: 00003 | B23: Client 003 Holdings | C23: 46354 | D23: 2026-11 | E23: fixed income | F23: 5158140
A24: 00004 | B24: Client 004 Holdings | C24: 46323 | D24: 2026-10 | E24: balanced | F24: 120000
A25: 00004 | B25: Client 004 Holdings | C25: 46354 | D25: 2026-11 | E25: balanced | F25: 124800
A26: 00005 | B26: Client 005 Holdings | C26: 46323 | D26: 2026-10 | E26: equity | F26: 23039688
A27: 00005 | B27: Client 005 Holdings | C27: 46354 | D27: 2026-11 | E27: equity | F27: 66635792
A28: 00006 | B28: Client 006 Holdings | C28: 46323 | D28: 2026-10 | E28: fixed income | F28: 63333653
A29: 00006 | B29: Client 006 Holdings | C29: 46354 | D29: 2026-11 | E29: fixed income | F29: 10520984
... A185: 00084 | B185: Client 084 Holdings | C185: 46354 | D185: 2026-11 | E185: fixed income | F185: 10047100

Sheet Fee Schedule
A1: Fee schedule -- from Client Onboarding, effective 2026-11-01
A2: Do not edit. Superseded schedules are kept on the shared drive.
H3: Minimum fee | I3: 750
A4: client_code | B4: negotiated_bps | D4: band_floor | E4: band_ceiling | F4: band_bps | H4: Maximum fee | I4: 250000
A5: 00001 | B5: 20.0 | D5: 0 | E5: 5000000 | F5: 35 | H5: Standard discount | I5: 0.025
A6: 00006 | B6: 27.5 | D6: 5000000 | E6: 20000000 | F6: 27.5
A7: 00011 | B7: 21.5 | D7: 20000000 | E7: 50000000 | F7: 22
A8: 00016 | B8: 29.0 | D8: 50000000 | E8: 100000000 | F8: 18.5
A9: 00021 | B9: 23.0
A10: 00026 | B10: 30.5
A11: 00031 | B11: 24.5
A12: 00036 | B12: 32.0
A13: 00041 | B13: 26.0
A14: 00046 | B14: 20.0
A15: 00051 | B15: 27.5
A16: 00056 | B16: 21.5
A17: 00061 | B17: 29.0
A18: 00066 | B18: 23.0
A19: 00071 | B19: 30.5
A20: 00076 | B20: 24.5
A21: 00081 | B21: 32.0

Sheet Working
A1: Management fee working -- November 2026
A3: Period | B3: 2026-11
A4: Prepared by | B4: Billing Operations
A14: 2024 flat rate (bps) | B14: 26
A15: 2024 adjustment factor | B15: 0.97
A18: Client | B18: Name | C18: On b'd | D18: Bill from | E18: Mth | F18: Nov-26 avg AUM | G18: Prior mth close | H18: Opening bal. | I18: Tier (bps) | J18: Tier bps | K18: Entity | L18: C/C | M18: Fee @ tier | N18: Days in mth | O18: Days b'ld | P18: Fee (p/r) | Q18: Fee after min | R18: Fee after max | S18: Disc'nt | T18: Adj'd fee (net) | U18: Fee agreed w/ client | V18: O/R? | W18: Inv. ref | X18: # posns | Y18: Running tot. | Z18: Mandate (clean) | AA18: AUM in mandate | AB18: % of mandate | AC18: AUM chk (Oct & Nov) | AD18: Band (A/B/C) | AE18: # a/cs | AF18: Data as at | AG18: Yr | AH18: 2024 fee | AI18: 2024 adj | AJ18: 2024 adj. | AK18: 2024 adj ref
A19: 00001 | B19: =INDEX('Entity Map'!$B:$B,MATCH(A19,'Entity Map'!$A:$A,0)) -> Client 001 Holdings | C19: =INDEX('Entity Map'!$F:$F,MATCH(A19,'Entity Map'!$A:$A,0)) -> 45352 | D19: =MAX(DATE(2026,11,1),C19) -> 46327 | E19: =TEXT(D19,"yyyy-mm") -> 2026-11 | F19: =AVERAGEIFS(Positions!$F:$F,Positions!$A:$A,A19) -> 11538990 | G19: =F19 -> 11538990 | H19: =IF(A19=A19,G19,F19) -> 11538990 | I19: =VLOOKUP(F19,'Fee Schedule'!$D$5:$F$8,3,TRUE) -> 27.5 | J19: =IFERROR(VLOOKUP(A19,'Fee Schedule'!$A$5:$B$21,2,FALSE),I19) -> 20.0 | K19: =INDEX('Entity Map'!$C:$C,MATCH(A19,'Entity Map'!$A:$A,0)) -> LuxCo | L19: =INDEX('Entity Map'!$D:$D,MATCH(A19,'Entity Map'!$A:$A,0)) -> CC-100 | M19: =ROUND(F19*J19/10000,2) -> 23077.98 | N19: =DAY(EOMONTH(D19,0)) -> 30 | O19: =DATEDIF(D19,EOMONTH(D19,0),"d")+1 -> 30 | P19: =ROUND(M19*O19/N19,2) -> 23077.98 | Q19: =MAX(P19,'Fee Schedule'!$I$3) -> 23077.98 | R19: =MIN(Q19,'Fee Schedule'!$I$4) -> 23077.98 | S19: =IFERROR(R19*'Fee Schedule'!$I$5,0) -> 576.9495 | T19: =ROUND(R19-S19,2) -> 22501.03 | U19: =IFERROR(VLOOKUP(A19,Overrides!$A:$C,3,FALSE),T19) -> 22501.03 | V19: =IF(U19=T19,"","OVERRIDE") | W19: =LEFT(A19,3)&"-"&E19 -> 000-2026-11 | X19: =COUNTIFS(Positions!$A:$A,A19) -> 2 | Y19: =SUM($U$19:U19) -> 22501.03 | Z19: =UPPER(TRIM(INDEX('Entity Map'!$E:$E,MATCH(A19,'Entity Map'!$A:$A,0)))) -> BALANCED | AA19: =SUMIFS(Positions!$F:$F,Positions!$E:$E,Z19) -> 2.4207534e+09 | AB19: =IFERROR(F19/AA19,0) -> 0.0047666937 | AC19: =SUMPRODUCT(Positions!$F$18:$F$185,--(Positions!$A$18:$A$185=A19)) -> 23077980 | AD19: =IF(U19>40000,"A",IF(U19>8000,"B","C")) -> B | AE19: =COUNTIF('Entity Map'!$A:$A,A19) -> 1 | AF19: =MAX(Positions!$C:$C) -> 46354 | AG19: =YEAR(D19) -> 2026 | AH19: =ROUND(F19*$B$14/10000,2) -> 30001.37 | AI19: =AH19-T19 -> 7500.34 | AJ19: =AI19*$B$15 -> 7275.3298 | AK19: =CONCATENATE(A19," / ",TEXT(AJ19,"0.00")) -> 00001 / 7275.33
A20: 00002 | B20: =INDEX('Entity Map'!$B:$B,MATCH(A20,'Entity Map'!$A:$A,0)) -> Client 002 Holdings | C20: =INDEX('Entity Map'!$F:$F,MATCH(A20,'Entity Map'!$A:$A,0)) -> 45353 | D20: =MAX(DATE(2026,11,1),C20) -> 46327 | E20: =TEXT(D20,"yyyy-mm") -> 2026-11 | F20: =AVERAGEIFS(Positions!$F:$F,Positions!$A:$A,A20) -> 53349311 | G20: =F19 -> 11538990 | H20: =IF(A20=A19,G20,F20) -> 53349311 | I20: =VLOOKUP(F20,'Fee Schedule'!$D$5:$F$8,3,TRUE) -> 18.5 | J20: =IFERROR(VLOOKUP(A20,'Fee Schedule'!$A$5:$B$21,2,FALSE),I20) -> 18.5 | K20: =INDEX('Entity Map'!$C:$C,MATCH(A20,'Entity Map'!$A:$A,0)) -> UKCo | L20: =INDEX('Entity Map'!$D:$D,MATCH(A20,'Entity Map'!$A:$A,0)) -> CC-110 | M20: =ROUND(F20*J20/10000,2) -> 98696.22 | N20: =DAY(EOMONTH(D20,0)) -> 30 | O20: =DATEDIF(D20,EOMONTH(D20,0),"d")+1 -> 30 | P20: =ROUND(M20*O20/N20,2) -> 98696.22 | Q20: =MAX(P20,'Fee Schedule'!$I$3) -> 98696.22 | R20: =MIN(Q20,'Fee Schedule'!$I$4) -> 98696.22 | S20: =IFERROR(R20*'Fee Schedule'!$I$5,0) -> 2467.4055 | T20: =ROUND(R20-S20,2) -> 96228.81 | U20: =IFERROR(VLOOKUP(A20,Overrides!$A:$C,3,FALSE),T20) -> 96228.81 | V20: =IF(U20=T20,"","OVERRIDE") | W20: =LEFT(A20,3)&"-"&E20 -> 000-2026-11 | X20: =COUNTIFS(Positions!$A:$A,A20) -> 2 | Y20: =SUM($U$19:U20) -> 118729.84 | Z20: =UPPER(TRIM(INDEX('Entity Map'!$E:$E,MATCH(A20,'Entity Map'!$A:$A,0)))) -> EQUITY | AA20: =SUMIFS(Positions!$F:$F,Positions!$E:$E,Z20) -> 2.8063116e+09 | AB20: =IFERROR(F20/AA20,0) -> 0.019010473 | AC20: =SUMPRODUCT(Positions!$F$18:$F$185,--(Positions!$A$18:$A$185=A20)) -> 1.0669862e+08 | AD20: =IF(U20>40000,"A",IF(U20>8000,"B","C")) -> A | AE20: =COUNTIF('Entity Map'!$A:$A,A20) -> 1 | AF20: =MAX(Positions!$C:$C) -> 46354 | AG20: =YEAR(D20) -> 2026 | AH20: =ROUND(F20*$B$14/10000,2) -> 138708.21 | AI20: =AH20-T20 -> 42479.4 | AJ20: =AI20*$B$15 -> 41205.018 | AK20: =CONCATENATE(A20," / ",TEXT(AJ20,"0.00")) -> 00002 / 41205.02
A21: 00003 | B21: =INDEX('Entity Map'!$B:$B,MATCH(A21,'Entity Map'!$A:$A,0)) -> Client 003 Holdings | C21: =INDEX('Entity Map'!$F:$F,MATCH(A21,'Entity Map'!$A:$A,0)) -> 45354 | D21: =MAX(DATE(2026,11,1),C21) -> 46327 | E21: =TEXT(D21,"yyyy-mm") -> 2026-11 | F21: =AVERAGEIFS(Positions!$F:$F,Positions!$A:$A,A21) -> 39322828 | G21: =F20 -> 53349311 | H21: =IF(A21=A20,G21,F21) -> 39322828 | I21: =VLOOKUP(F21,'Fee Schedule'!$D$5:$F$8,3,TRUE) -> 22 | J21: =IFERROR(VLOOKUP(A21,'Fee Schedule'!$A$5:$B$21,2,FALSE),I21) -> 22 | K21: =INDEX('Entity Map'!$C:$C,MATCH(A21,'Entity Map'!$A:$A,0)) -> DubCo | L21: =INDEX('Entity Map'!$D:$D,MATCH(A21,'Entity Map'!$A:$A,0)) -> CC-120 | M21: =ROUND(F21*J21/10000,2) -> 86510.22 | N21: =DAY(EOMONTH(D21,0)) -> 30 | O21: =DATEDIF(D21,EOMONTH(D21,0),"d")+1 -> 30 | P21: =ROUND(M21*O21/N21,2) -> 86510.22 | Q21: =MAX(P21,'Fee Schedule'!$I$3) -> 86510.22 | R21: =MIN(Q21,'Fee Schedule'!$I$4) -> 86510.22 | S21: =IFERROR(R21*'Fee Schedule'!$I$5,0) -> 2162.7555 | T21: =ROUND(R21-S21,2) -> 84347.46 | U21: =IFERROR(VLOOKUP(A21,Overrides!$A:$C,3,FALSE),T21) -> 84347.46 | V21: =IF(U21=T21,"","OVERRIDE") | W21: =LEFT(A21,3)&"-"&E21 -> 000-2026-11 | X21: =COUNTIFS(Positions!$A:$A,A21) -> 2 | Y21: =SUM($U$19:U21) -> 203077.3 | Z21: =UPPER(TRIM(INDEX('Entity Map'!$E:$E,MATCH(A21,'Entity Map'!$A:$A,0)))) -> FIXED INCOME | AA21: =SUMIFS(Positions!$F:$F,Positions!$E:$E,Z21) -> 2.496646e+09 | AB21: =IFERROR(F21/AA21,0) -> 0.015750262 | AC21: =SUMPRODUCT(Positions!$F$18:$F$185,--(Positions!$A$18:$A$185=A21)) -> 78645655 | AD21: =IF(U21>40000,"A",IF(U21>8000,"B","C")) -> A | AE21: =COUNTIF('Entity Map'!$A:$A,A21) -> 1 | AF21: =MAX(Positions!$C:$C) -> 46354 | AG21: =YEAR(D21) -> 2026 | AH21: =ROUND(F21*$B$14/10000,2) -> 102239.35 | AI21: =AH21-T21 -> 17891.89 | AJ21: =AI21*$B$15 -> 17355.133 | AK21: =CONCATENATE(A21," / ",TEXT(AJ21,"0.00")) -> 00003 / 17355.13
A22: 00004 | B22: =INDEX('Entity Map'!$B:$B,MATCH(A22,'Entity Map'!$A:$A,0)) -> Client 004 Holdings | C22: =INDEX('Entity Map'!$F:$F,MATCH(A22,'Entity Map'!$A:$A,0)) -> 45355 | D22: =MAX(DATE(2026,11,1),C22) -> 46327 | E22: =TEXT(D22,"yyyy-mm") -> 2026-11 | F22: =AVERAGEIFS(Positions!$F:$F,Positions!$A:$A,A22) -> 122400 | G22: =F21 -> 39322828 | H22: =IF(A22=A21,G22,F22) -> 122400 | I22: =VLOOKUP(F22,'Fee Schedule'!$D$5:$F$8,3,TRUE) -> 35 | J22: =IFERROR(VLOOKUP(A22,'Fee Schedule'!$A$5:$B$21,2,FALSE),I22) -> 35 | K22: =INDEX('Entity Map'!$C:$C,MATCH(A22,'Entity Map'!$A:$A,0)) -> LuxCo | L22: =INDEX('Entity Map'!$D:$D,MATCH(A22,'Entity Map'!$A:$A,0)) -> CC-130 | M22: =ROUND(F22*J22/10000,2) -> 428.4 | N22: =DAY(EOMONTH(D22,0)) -> 30 | O22: =DATEDIF(D22,EOMONTH(D22,0),"d")+1 -> 30 | P22: =ROUND(M22*O22/N22,2) -> 428.4 | Q22: =MAX(P22,'Fee Schedule'!$I$3) -> 750 | R22: =MIN(Q22,'Fee Schedule'!$I$4) -> 750 | S22: =IFERROR(R22*'Fee Schedule'!$I$5,0) -> 18.75 | T22: =ROUND(R22-S22,2) -> 731.25 | U22: =IFERROR(VLOOKUP(A22,Overrides!$A:$C,3,FALSE),T22) -> 731.25 | V22: =IF(U22=T22,"","OVERRIDE") | W22: =LEFT(A22,3)&"-"&E22 -> 000-2026-11 | X22: =COUNTIFS(Positions!$A:$A,A22) -> 2 | Y22: =SUM($U$19:U22) -> 203808.55 | Z22: =UPPER(TRIM(INDEX('Entity Map'!$E:$E,MATCH(A22,'Entity Map'!$A:$A,0)))) -> BALANCED | AA22: =SUMIFS(Positions!$F:$F,Positions!$E:$E,Z22) -> 2.4207534e+09 | AB22: =IFERROR(F22/AA22,0) -> 5.0562771e-05 | AC22: =SUMPRODUCT(Positions!$F$18:$F$185,--(Positions!$A$18:$A$185=A22)) -> 244800 | AD22: =IF(U22>40000,"A",IF(U22>8000,"B","C")) -> C | AE22: =COUNTIF('Entity Map'!$A:$A,A22) -> 1 | AF22: =MAX(Positions!$C:$C) -> 46354 | AG22: =YEAR(D22) -> 2026 | AH22: =ROUND(F22*$B$14/10000,2) -> 318.24 | AI22: =AH22-T22 -> -413.01 | AJ22: =AI22*$B$15 -> -400.6197 | AK22: =CONCATENATE(A22," / ",TEXT(AJ22,"0.00")) -> 00004 / -400.62
A23: 00005 | B23: =INDEX('Entity Map'!$B:$B,MATCH(A23,'Entity Map'!$A:$A,0)) -> Client 005 Holdings | C23: =INDEX('Entity Map'!$F:$F,MATCH(A23,'Entity Map'!$A:$A,0)) -> 45356 | D23: =MAX(DATE(2026,11,1),C23) -> 46327 | E23: =TEXT(D23,"yyyy-mm") -> 2026-11 | F23: =AVERAGEIFS(Positions!$F:$F,Positions!$A:$A,A23) -> 44837740 | G23: =F22 -> 122400 | H23: =IF(A23=A22,G23,F23) -> 44837740 | I23: =VLOOKUP(F23,'Fee Schedule'!$D$5:$F$8,3,TRUE) -> 22 | J23: =IFERROR(VLOOKUP(A23,'Fee Schedule'!$A$5:$B$21,2,FALSE),I23) -> 22 | K23: =INDEX('Entity Map'!$C:$C,MATCH(A23,'Entity Map'!$A:$A,0)) -> UKCo | L23: =INDEX('Entity Map'!$D:$D,MATCH(A23,'Entity Map'!$A:$A,0)) -> CC-140 | M23: =ROUND(F23*J23/10000,2) -> 98643.03 | N23: =DAY(EOMONTH(D23,0)) -> 30 | O23: =DATEDIF(D23,EOMONTH(D23,0),"d")+1 -> 30 | P23: =ROUND(M23*O23/N23,2) -> 98643.03 | Q23: =MAX(P23,'Fee Schedule'!$I$3) -> 98643.03 | R23: =MIN(Q23,'Fee Schedule'!$I$4) -> 98643.03 | S23: =IFERROR(R23*'Fee Schedule'!$I$5,0) -> 2466.0757 | T23: =ROUND(R23-S23,2) -> 96176.95 | U23: =IFERROR(VLOOKUP(A23,Overrides!$A:$C,3,FALSE),T23) -> 96176.95 | V23: =IF(U23=T23,"","OVERRIDE") | W23: =LEFT(A23,3)&"-"&E23 -> 000-2026-11 | X23: =COUNTIFS(Positions!$A:$A,A23) -> 2 | Y23: =SUM($U$19:U23) -> 299985.5 | Z23: =UPPER(TRIM(INDEX('Entity Map'!$E:$E,MATCH(A23,'Entity Map'!$A:$A,0)))) -> EQUITY | AA23: =SUMIFS(Positions!$F:$F,Positions!$E:$E,Z23) -> 2.8063116e+09 | AB23: =IFERROR(F23/AA23,0) -> 0.015977463 | AC23: =SUMPRODUCT(Positions!$F$18:$F$185,--(Positions!$A$18:$A$185=A23)) -> 89675481 | AD23: =IF(U23>40000,"A",IF(U23>8000,"B","C")) -> A | AE23: =COUNTIF('Entity Map'!$A:$A,A23) -> 1 | AF23: =MAX(Positions!$C:$C) -> 46354 | AG23: =YEAR(D23) -> 2026 | AH23: =ROUND(F23*$B$14/10000,2) -> 116578.12 | AI23: =AH23-T23 -> 20401.17 | AJ23: =AI23*$B$15 -> 19789.135 | AK23: =CONCATENATE(A23," / ",TEXT(AJ23,"0.00")) -> 00005 / 19789.13
A24: 00006 | B24: =INDEX('Entity Map'!$B:$B,MATCH(A24,'Entity Map'!$A:$A,0)) -> Client 006 Holdings | C24: =INDEX('Entity Map'!$F:$F,MATCH(A24,'Entity Map'!$A:$A,0)) -> 45357 | D24: =MAX(DATE(2026,11,1),C24) -> 46327 | E24: =TEXT(D24,"yyyy-mm") -> 2026-11 | F24: =AVERAGEIFS(Positions!$F:$F,Positions!$A:$A,A24) -> 36927318 | G24: =F23 -> 44837740 | H24: =IF(A24=A23,G24,F24) -> 36927318 | I24: =VLOOKUP(F24,'Fee Schedule'!$D$5:$F$8,3,TRUE) -> 22 | J24: =IFERROR(VLOOKUP(A24,'Fee Schedule'!$A$5:$B$21,2,FALSE),I24) -> 27.5 | K24: =INDEX('Entity Map'!$C:$C,MATCH(A24,'Entity Map'!$A:$A,0)) -> DubCo | L24: =INDEX('Entity Map'!$D:$D,MATCH(A24,'Entity Map'!$A:$A,0)) -> CC-150 | M24: =ROUND(F24*J24/10000,2) -> 101550.13 | N24: =DAY(EOMONTH(D24,0)) -> 30 | O24: =DATEDIF(D24,EOMONTH(D24,0),"d")+1 -> 30 | P24: =ROUND(M24*O24/N24,2) -> 101550.13 | Q24: =MAX(P24,'Fee Schedule'!$I$3) -> 101550.13 | R24: =MIN(Q24,'Fee Schedule'!$I$4) -> 101550.13 | S24: =IFERROR(R24*'Fee Schedule'!$I$5,0) -> 2538.7533 | T24: =ROUND(R24-S24,2) -> 99011.38 | U24: =IFERROR(VLOOKUP(A24,Overrides!$A:$C,3,FALSE),T24) -> 99011.38 | V24: =IF(U24=T24,"","OVERRIDE") | W24: =LEFT(A24,3)&"-"&E24 -> 000-2026-11 | X24: =COUNTIFS(Positions!$A:$A,A24) -> 2 | Y24: =SUM($U$19:U24) -> 398996.88 | Z24: =UPPER(TRIM(INDEX('Entity Map'!$E:$E,MATCH(A24,'Entity Map'!$A:$A,0)))) -> FIXED INCOME | AA24: =SUMIFS(Positions!$F:$F,Positions!$E:$E,Z24) -> 2.496646e+09 | AB24: =IFERROR(F24/AA24,0) -> 0.014790771 | AC24: =SUMPRODUCT(Positions!$F$18:$F$185,--(Positions!$A$18:$A$185=A24)) -> 73854637 | AD24: =IF(U24>40000,"A",IF(U24>8000,"B","C")) -> A | AE24: =COUNTIF('Entity Map'!$A:$A,A24) -> 1 | AF24: =MAX(Positions!$C:$C) -> 46354 | AG24: =YEAR(D24) -> 2026 | AH24: =ROUND(F24*$B$14/10000,2) -> 96011.03 | AI24: =AH24-T24 -> -3000.35 | AJ24: =AI24*$B$15 -> -2910.3395 | AK24: =CONCATENATE(A24," / ",TEXT(AJ24,"0.00")) -> 00006 / -2910.34
A25: 00007 | B25: =INDEX('Entity Map'!$B:$B,MATCH(A25,'Entity Map'!$A:$A,0)) -> Client 007 Holdings | C25: =INDEX('Entity Map'!$F:$F,MATCH(A25,'Entity Map'!$A:$A,0)) -> 45358 | D25: =MAX(DATE(2026,11,1),C25) -> 46327 | E25: =TEXT(D25,"yyyy-mm") -> 2026-11 | F25: =AVERAGEIFS(Positions!$F:$F,Positions!$A:$A,A25) -> 29063097 | G25: =F24 -> 36927318 | H25: =IF(A25=A24,G25,F25) -> 29063097 | I25: =VLOOKUP(F25,'Fee Schedule'!$D$5:$F$8,3,TRUE) -> 22 | J25: =IFERROR(VLOOKUP(A25,'Fee Schedule'!$A$5:$B$21,2,FALSE),I25) -> 22 | K25: =INDEX('Entity Map'!$C:$C,MATCH(A25,'Entity Map'!$A:$A,0)) -> LuxCo | L25: =INDEX('Entity Map'!$D:$D,MATCH(A25,'Entity Map'!$A:$A,0)) -> CC-100 | M25: =ROUND(F25*J25/10000,2) -> 63938.81 | N25: =DAY(EOMONTH(D25,0)) -> 30 | O25: =DATEDIF(D25,EOMONTH(D25,0),"d")+1 -> 30 | P25: =ROUND(M25*O25/N25,2) -> 63938.81 | Q25: =MAX(P25,'Fee Schedule'!$I$3) -> 63938.81 | R25: =MIN(Q25,'Fee Schedule'!$I$4) -> 63938.81 | S25: =IFERROR(R25*'Fee Schedule'!$I$5,0) -> 1598.4703 | T25: =ROUND(R25-S25,2) -> 62340.34 | U25: =IFERROR(VLOOKUP(A25,Overrides!$A:$C,3,FALSE),T25) -> 0 | V25: =IF(U25=T25,"","OVERRIDE") -> OVERRIDE | W25: =LEFT(A25,3)&"-"&E25 -> 000-2026-11 | X25: =COUNTIFS(Positions!$A:$A,A25) -> 2 | Y25: =SUM($U$19:U25) -> 398996.88 | Z25: =UPPER(TRIM(INDEX('Entity Map'!$E:$E,MATCH(A25,'Entity Map'!$A:$A,0)))) -> BALANCED | AA25: =SUMIFS(Positions!$F:$F,Positions!$E:$E,Z25) -> 2.4207534e+09 | AB25: =IFERROR(F25/AA25,0) -> 0.012005807 | AC25: =SUMPRODUCT(Positions!$F$18:$F$185,--(Positions!$A$18:$A$185=A25)) -> 58126195 | AD25: =IF(U25>40000,"A",IF(U25>8000,"B","C")) -> C | AE25: =COUNTIF('Entity Map'!$A:$A,A25) -> 1 | AF25: =MAX(Positions!$C:$C) -> 46354 | AG25: =YEAR(D25) -> 2026 | AH25: =ROUND(F25*$B$14/10000,2) -> 75564.05 | AI25: =AH25-T25 -> 13223.71 | AJ25: =AI25*$B$15 -> 12826.999 | AK25: =CONCATENATE(A25," / ",TEXT(AJ25,"0.00")) -> 00007 / 12827.00
A26: 00008 | B26: =INDEX('Entity Map'!$B:$B,MATCH(A26,'Entity Map'!$A:$A,0)) -> Client 008 Holdings | C26: =INDEX('Entity Map'!$F:$F,MATCH(A26,'Entity Map'!$A:$A,0)) -> 45359 | D26: =MAX(DATE(2026,11,1),C26) -> 46327 | E26: =TEXT(D26,"yyyy-mm") -> 2026-11 | F26: =AVERAGEIFS(Positions!$F:$F,Positions!$A:$A,A26) -> 37175444 | G26: =F25 -> 29063097 | H26: =IF(A26=A25,G26,F26) -> 37175444 | I26: =VLOOKUP(F26,'Fee Schedule'!$D$5:$F$8,3,TRUE) -> 22 | J26: =IFERROR(VLOOKUP(A26,'Fee Schedule'!$A$5:$B$21,2,FALSE),I26) -> 22 | K26: =INDEX('Entity Map'!$C:$C,MATCH(A26,'Entity Map'!$A:$A,0)) -> UKCo | L26: =INDEX('Entity Map'!$D:$D,MATCH(A26,'Entity Map'!$A:$A,0)) -> CC-110 | M26: =ROUND(F26*J26/10000,2) -> 81785.98 | N26: =DAY(EOMONTH(D26,0)) -> 30 | O26: =DATEDIF(D26,EOMONTH(D26,0),"d")+1 -> 30 | P26: =ROUND(M26*O26/N26,2) -> 81785.98 | Q26: =MAX(P26,'Fee Schedule'!$I$3) -> 81785.98 | R26: =MIN(Q26,'Fee Schedule'!$I$4) -> 81785.98 | S26: =IFERROR(R26*'Fee Schedule'!$I$5,0) -> 2044.6495 | T26: =ROUND(R26-S26,2) -> 79741.33 | U26: =IFERROR(VLOOKUP(A26,Overrides!$A:$C,3,FALSE),T26) -> 79741.33 | V26: =IF(U26=T26,"","OVERRIDE") | W26: =LEFT(A26,3)&"-"&E26 -> 000-2026-11 | X26: =COUNTIFS(Positions!$A:$A,A26) -> 2 | Y26: =SUM($U$19:U26) -> 478738.21 | Z26: =UPPER(TRIM(INDEX('Entity Map'!$E:$E,MATCH(A26,'Entity Map'!$A:$A,0)))) -> EQUITY | AA26: =SUMIFS(Positions!$F:$F,Positions!$E:$E,Z26) -> 2.8063116e+09 | AB26: =IFERROR(F26/AA26,0) -> 0.013247083 | AC26: =SUMPRODUCT(Positions!$F$18:$F$185,--(Positions!$A$18:$A$185=A26)) -> 74350888 | AD26: =IF(U26>40000,"A",IF(U26>8000,"B","C")) -> A | AE26: =COUNTIF('Entity Map'!$A:$A,A26) -> 1 | AF26: =MAX(Positions!$C:$C) -> 46354 | AG26: =YEAR(D26) -> 2026 | AH26: =ROUND(F26*$B$14/10000,2) -> 96656.15 | AI26: =AH26-T26 -> 16914.82 | AJ26: =AI26*$B$15 -> 16407.375 | AK26: =CONCATENATE(A26," / ",TEXT(AJ26,"0.00")) -> 00008 / 16407.38
A27: 00009 | B27: =INDEX('Entity Map'!$B:$B,MATCH(A27,'Entity Map'!$A:$A,0)) -> Client 009 Holdings | C27: =INDEX('Entity Map'!$F:$F,MATCH(A27,'Entity Map'!$A:$A,0)) -> 45360 | D27: =MAX(DATE(2026,11,1),C27) -> 46327 | E27: =TEXT(D27,"yyyy-mm") -> 2026-11 | F27: =AVERAGEIFS(Positions!$F:$F,Positions!$A:$A,A27) -> 47933385 | G27: =F26 -> 37175444 | H27: =IF(A27=A26,G27,F27) -> 47933385 | I27: =VLOOKUP(F27,'Fee Schedule'!$D$5:$F$8,3,TRUE) -> 22 | J27: =IFERROR(VLOOKUP(A27,'Fee Schedule'!$A$5:$B$21,2,FALSE),I27) -> 22 | K27: =INDEX('Entity Map'!$C:$C,MATCH(A27,'Entity Map'!$A:$A,0)) -> DubCo | L27: =INDEX('Entity Map'!$D:$D,MATCH(A27,'Entity Map'!$A:$A,0)) -> CC-120 | M27: =ROUND(F27*J27/10000,2) -> 105453.45 | N27: =DAY(EOMONTH(D27,0)) -> 30 | O27: =DATEDIF(D27,EOMONTH(D27,0),"d")+1 -> 30 | P27: =ROUND(M27*O27/N27,2) -> 105453.45 | Q27: =MAX(P27,'Fee Schedule'!$I$3) -> 105453.45 | R27: =MIN(Q27,'Fee Schedule'!$I$4) -> 105453.45 | S27: =IFERROR(R27*'Fee Schedule'!$I$5,0) -> 2636.3363 | T27: =ROUND(R27-S27,2) -> 102817.11 | U27: =IFERROR(VLOOKUP(A27,Overrides!$A:$C,3,FALSE),T27) -> 102817.11 | V27: =IF(U27=T27,"","OVERRIDE") | W27: =LEFT(A27,3)&"-"&E27 -> 000-2026-11 | X27: =COUNTIFS(Positions!$A:$A,A27) -> 2 | Y27: =SUM($U$19:U27) -> 581555.32 | Z27: =UPPER(TRIM(INDEX('Entity Map'!$E:$E,MATCH(A27,'Entity Map'!$A:$A,0)))) -> FIXED INCOME | AA27: =SUMIFS(Positions!$F:$F,Positions!$E:$E,Z27) -> 2.496646e+09 | AB27: =IFERROR(F27/AA27,0) -> 0.019199112 | AC27: =SUMPRODUCT(Positions!$F$18:$F$185,--(Positions!$A$18:$A$185=A27)) -> 95866770 | AD27: =IF(U27>40000,"A",IF(U27>8000,"B","C")) -> A | AE27: =COUNTIF('Entity Map'!$A:$A,A27) -> 1 | AF27: =MAX(Positions!$C:$C) -> 46354 | AG27: =YEAR(D27) -> 2026 | AH27: =ROUND(F27*$B$14/10000,2) -> 124626.8 | AI27: =AH27-T27 -> 21809.69 | AJ27: =AI27*$B$15 -> 21155.399 | AK27: =CONCATENATE(A27," / ",TEXT(AJ27,"0.00")) -> 00009 / 21155.40
A28: 00010 | B28: =INDEX('Entity Map'!$B:$B,MATCH(A28,'Entity Map'!$A:$A,0)) -> Client 010 Holdings | C28: =INDEX('Entity Map'!$F:$F,MATCH(A28,'Entity Map'!$A:$A,0)) -> 45361 | D28: =MAX(DATE(2026,11,1),C28) -> 46327 | E28: =TEXT(D28,"yyyy-mm") -> 2026-11 | F28: =AVERAGEIFS(Positions!$F:$F,Positions!$A:$A,A28) -> 54863921 | G28: =F27 -> 47933385 | H28: =IF(A28=A27,G28,F28) -> 54863921 | I28: =VLOOKUP(F28,'Fee Schedule'!$D$5:$F$8,3,TRUE) -> 18.5 | J28: =IFERROR(VLOOKUP(A28,'Fee Schedule'!$A$5:$B$21,2,FALSE),I28) -> 18.5 | K28: =INDEX('Entity Map'!$C:$C,MATCH(A28,'Entity Map'!$A:$A,0)) -> LuxCo | L28: =INDEX('Entity Map'!$D:$D,MATCH(A28,'Entity Map'!$A:$A,0)) -> CC-130 | M28: =ROUND(F28*J28/10000,2) -> 101498.25 | N28: =DAY(EOMONTH(D28,0)) -> 30 | O28: =DATEDIF(D28,EOMONTH(D28,0),"d")+1 -> 30 | P28: =ROUND(M28*O28/N28,2) -> 101498.25 | Q28: =MAX(P28,'Fee Schedule'!$I$3) -> 101498.25 | R28: =MIN(Q28,'Fee Schedule'!$I$4) -> 101498.25 | S28: =IFERROR(R28*'Fee Schedule'!$I$5,0) -> 2537.4563 | T28: =ROUND(R28-S28,2) -> 98960.79 | U28: =IFERROR(VLOOKUP(A28,Overrides!$A:$C,3,FALSE),T28) -> 98960.79 | V28: =IF(U28=T28,"","OVERRIDE") | W28: =LEFT(A28,3)&"-"&E28 -> 000-2026-11 | X28: =COUNTIFS(Positions!$A:$A,A28) -> 2 | Y28: =SUM($U$19:U28) -> 680516.11 | Z28: =UPPER(TRIM(INDEX('Entity Map'!$E:$E,MATCH(A28,'Entity Map'!$A:$A,0)))) -> BALANCED | AA28: =SUMIFS(Positions!$F:$F,Positions!$E:$E,Z28) -> 2.4207534e+09 | AB28: =IFERROR(F28/AA28,0) -> 0.022663986 | AC28: =SUMPRODUCT(Positions!$F$18:$F$185,--(Positions!$A$18:$A$185=A28)) -> 1.0972784e+08 | AD28: =IF(U28>40000,"A",IF(U28>8000,"B","C")) -> A | AE28: =COUNTIF('Entity Map'!$A:$A,A28) -> 1 | AF28: =MAX(Positions!$C:$C) -> 46354 | AG28: =YEAR(D28) -> 2026 | AH28: =ROUND(F28*$B$14/10000,2) -> 142646.19 | AI28: =AH28-T28 -> 43685.4 | AJ28: =AI28*$B$15 -> 42374.838 | AK28: =CONCATENATE(A28," / ",TEXT(AJ28,"0.00")) -> 00010 / 42374.84
A29: 00011 | B29: =INDEX('Entity Map'!$B:$B,MATCH(A29,'Entity Map'!$A:$A,0)) -> Client 011 Holdings | C29: =INDEX('Entity Map'!$F:$F,MATCH(A29,'Entity Map'!$A:$A,0)) -> 45362 | D29: =MAX(DATE(2026,11,1),C29) -> 46327 | E29: =TEXT(D29,"yyyy-mm") -> 2026-11 | F29: =AVERAGEIFS(Positions!$F:$F,Positions!$A:$A,A29) -> 16406934 | G29: =F28 -> 54863921 | H29: =IF(A29=A28,G29,F29) -> 16406934 | I29: =VLOOKUP(F29,'Fee Schedule'!$D$5:$F$8,3,TRUE) -> 27.5 | J29: =IFERROR(VLOOKUP(A29,'Fee Schedule'!$A$5:$B$21,2,FALSE),I29) -> 21.5 | K29: =INDEX('Entity Map'!$C:$C,MATCH(A29,'Entity Map'!$A:$A,0)) -> UKCo | L29: =INDEX('Entity Map'!$D:$D,MATCH(A29,'Entity Map'!$A:$A,0)) -> CC-140 | M29: =ROUND(F29*J29/10000,2) -> 35274.91 | N29: =DAY(EOMONTH(D29,0)) -> 30 | O29: =DATEDIF(D29,EOMONTH(D29,0),"d")+1 -> 30 | P29: =ROUND(M29*O29/N29,2) -> 35274.91 | Q29: =MAX(P29,'Fee Schedule'!$I$3) -> 35274.91 | R29: =MIN(Q29,'Fee Schedule'!$I$4) -> 35274.91 | S29: =IFERROR(R29*'Fee Schedule'!$I$5,0) -> 881.87275 | T29: =ROUND(R29-S29,2) -> 34393.04 | U29: =IFERROR(VLOOKUP(A29,Overrides!$A:$C,3,FALSE),T29) -> 34393.04 | V29: =IF(U29=T29,"","OVERRIDE") | W29: =LEFT(A29,3)&"-"&E29 -> 000-2026-11 | X29: =COUNTIFS(Positions!$A:$A,A29) -> 2 | Y29: =SUM($U$19:U29) -> 714909.15 | Z29: =UPPER(TRIM(INDEX('Entity Map'!$E:$E,MATCH(A29,'Entity Map'!$A:$A,0)))) -> EQUITY | AA29: =SUMIFS(Positions!$F:$F,Positions!$E:$E,Z29) -> 2.8063116e+09 | AB29: =IFERROR(F29/AA29,0) -> 0.0058464406 | AC29: =SUMPRODUCT(Positions!$F$18:$F$185,--(Positions!$A$18:$A$185=A29)) -> 32813869 | AD29: =IF(U29>40000,"A",IF(U29>8000,"B","C")) -> B | AE29: =COUNTIF('Entity Map'!$A:$A,A29) -> 1 | AF29: =MAX(Positions!$C:$C) -> 46354 | AG29: =YEAR(D29) -> 2026 | AH29: =ROUND(F29*$B$14/10000,2) -> 42658.03 | AI29: =AH29-T29 -> 8264.99 | AJ29: =AI29*$B$15 -> 8017.0403 | AK29: =CONCATENATE(A29," / ",TEXT(AJ29,"0.00")) -> 00011 / 8017.04
A30: 00012 | B30: =INDEX('Entity Map'!$B:$B,MATCH(A30,'Entity Map'!$A:$A,0)) -> Client 012 Holdings | C30: =INDEX('Entity Map'!$F:$F,MATCH(A30,'Entity Map'!$A:$A,0)) -> 45363 | D30: =MAX(DATE(2026,11,1),C30) -> 46327 | E30: =TEXT(D30,"yyyy-mm") -> 2026-11 | F30: =AVERAGEIFS(Positions!$F:$F,Positions!$A:$A,A30) -> 13346471 | G30: =F29 -> 16406934 | H30: =IF(A30=A29,G30,F30) -> 13346471 | I30: =VLOOKUP(F30,'Fee Schedule'!$D$5:$F$8,3,TRUE) -> 27.5 | J30: =IFERROR(VLOOKUP(A30,'Fee Schedule'!$A$5:$B$21,2,FALSE),I30) -> 27.5 | K30: =INDEX('Entity Map'!$C:$C,MATCH(A30,'Entity Map'!$A:$A,0)) -> DubCo | L30: =INDEX('Entity Map'!$D:$D,MATCH(A30,'Entity Map'!$A:$A,0)) -> CC-150 | M30: =ROUND(F30*J30/10000,2) -> 36702.79 | N30: =DAY(EOMONTH(D30,0)) -> 30 | O30: =DATEDIF(D30,EOMONTH(D30,0),"d")+1 -> 30 | P30: =ROUND(M30*O30/N30,2) -> 36702.79 | Q30: =MAX(P30,'Fee Schedule'!$I$3) -> 36702.79 | R30: =MIN(Q30,'Fee Schedule'!$I$4) -> 36702.79 | S30: =IFERROR(R30*'Fee Schedule'!$I$5,0) -> 917.56975 | T30: =ROUND(R30-S30,2) -> 35785.22 | U30: =IFERROR(VLOOKUP(A30,Overrides!$A:$C,3,FALSE),T30) -> 35785.22 | V30: =IF(U30=T30,"","OVERRIDE") | W30: =LEFT(A30,3)&"-"&E30 -> 000-2026-11 | X30: =COUNTIFS(Positions!$A:$A,A30) -> 2 | Y30: =SUM($U$19:U30) -> 750694.37 | Z30: =UPPER(TRIM(INDEX('Entity Map'!$E:$E,MATCH(A30,'Entity Map'!$A:$A,0)))) -> FIXED INCOME | AA30: =SUMIFS(Positions!$F:$F,Positions!$E:$E,Z30) -> 2.496646e+09 | AB30: =IFERROR(F30/AA30,0) -> 0.0053457603 | AC30: =SUMPRODUCT(Positions!$F$18:$F$185,--(Positions!$A$18:$A$185=A30)) -> 26692942 | AD30: =IF(U30>40000,"A",IF(U30>8000,"B","C")) -> B | AE30: =COUNTIF('Entity Map'!$A:$A,A30) -> 1 | AF30: =MAX(Positions!$C:$C) -> 46354 | AG30: =YEAR(D30) -> 2026 | AH30: =ROUND(F30*$B$14/10000,2) -> 34700.82 | AI30: =AH30-T30 -> -1084.4 | AJ30: =AI30*$B$15 -> -1051.868 | AK30: =CONCATENATE(A30," / ",TEXT(AJ30,"0.00")) -> 00012 / -1051.87
A31: 00013 | B31: =INDEX('Entity Map'!$B:$B,MATCH(A31,'Entity Map'!$A:$A,0)) -> Client 013 Holdings | C31: =INDEX('Entity Map'!$F:$F,MATCH(A31,'Entity Map'!$A:$A,0)) -> 46338 | D31: =MAX(DATE(2026,11,1),C31) -> 46338 | E31: =TEXT(D31,"yyyy-mm") -> 2026-11 | F31: =AVERAGEIFS(Positions!$F:$F,Positions!$A:$A,A31) -> 26995267 | G31: =F30 -> 13346471 | H31: =IF(A31=A30,G31,F31) -> 26995267 | I31: =VLOOKUP(F31,'Fee Schedule'!$D$5:$F$8,3,TRUE) -> 22 | J31: =IFERROR(VLOOKUP(A31,'Fee Schedule'!$A$5:$B$21,2,FALSE),I31) -> 22 | K31: =INDEX('Entity Map'!$C:$C,MATCH(A31,'Entity Map'!$A:$A,0)) -> LuxCo | L31: =INDEX('Entity Map'!$D:$D,MATCH(A31,'Entity Map'!$A:$A,0)) -> CC-100 | M31: =ROUND(F31*J31/10000,2) -> 59389.59 | N31: =DAY(EOMONTH(D31,0)) -> 30 | O31: =DATEDIF(D31,EOMONTH(D31,0),"d")+1 -> 19 | P31: =ROUND(M31*O31/N31,2) -> 37613.41 | Q31: =MAX(P31,'Fee Schedule'!$I$3) -> 37613.41 | R31: =MIN(Q31,'Fee Schedule'!$I$4) -> 37613.41 | S31: =IFERROR(R31*'Fee Schedule'!$I$5,0) -> 940.33525 | T31: =ROUND(R31-S31,2) -> 36673.07 | U31: =IFERROR(VLOOKUP(A31,Overrides!$A:$C,3,FALSE),T31) -> 36673.07 | V31: =IF(U31=T31,"","OVERRIDE") | W31: =LEFT(A31,3)&"-"&E31 -> 000-2026-11 | X31: =COUNTIFS(Positions!$A:$A,A31) -> 2 | Y31: =SUM($U$19:U31) -> 787367.44 | Z31: =UPPER(TRIM(INDEX('Entity Map'!$E:$E,MATCH(A31,'Entity Map'!$A:$A,0)))) -> BALANCED | AA31: =SUMIFS(Positions!$F:$F,Positions!$E:$E,Z31) -> 2.4207534e+09 | AB31: =IFERROR(F31/AA31,0) -> 0.011151597 | AC31: =SUMPRODUCT(Positions!$F$18:$F$185,--(Positions!$A$18:$A$185=A31)) -> 53990534 | AD31: =IF(U31>40000,"A",IF(U31>8000,"B","C")) -> B | AE31: =COUNTIF('Entity Map'!$A:$A,A31) -> 1 | AF31: =MAX(Positions!$C:$C) -> 46354 | AG31: =YEAR(D31) -> 2026 | AH31: =ROUND(F31*$B$14/10000,2) -> 70187.69 | AI31: =AH31-T31 -> 33514.62 | AJ31: =AI31*$B$15 -> 32509.181 | AK31: =CONCATENATE(A31," / ",TEXT(AJ31,"0.00")) -> 00013 / 32509.18
... A102: 00084 | B102: =INDEX('Entity Map'!$B:$B,MATCH(A102,'Entity Map'!$A:$A,0)) -> Client 084 Holdings | C102: =INDEX('Entity Map'!$F:$F,MATCH(A102,'Entity Map'!$A:$A,0)) -> 45354 | D102: =MAX(DATE(2026,11,1),C102) -> 46327 | E102: =TEXT(D102,"yyyy-mm") -> 2026-11 | F102: =AVERAGEIFS(Positions!$F:$F,Positions!$A:$A,A102) -> 25077704 | G102: =F101 -> 55542240 | H102: =IF(A102=A101,G102,F102) -> 25077704 | I102: =VLOOKUP(F102,'Fee Schedule'!$D$5:$F$8,3,TRUE) -> 22 | J102: =IFERROR(VLOOKUP(A102,'Fee Schedule'!$A$5:$B$21,2,FALSE),I102) -> 22 | K102: =INDEX('Entity Map'!$C:$C,MATCH(A102,'Entity Map'!$A:$A,0)) -> DubCo | L102: =INDEX('Entity Map'!$D:$D,MATCH(A102,'Entity Map'!$A:$A,0)) -> CC-150 | M102: =ROUND(F102*J102/10000,2) -> 55170.95 | N102: =DAY(EOMONTH(D102,0)) -> 30 | O102: =DATEDIF(D102,EOMONTH(D102,0),"d")+1 -> 30 | P102: =ROUND(M102*O102/N102,2) -> 55170.95 | Q102: =MAX(P102,'Fee Schedule'!$I$3) -> 55170.95 | R102: =MIN(Q102,'Fee Schedule'!$I$4) -> 55170.95 | S102: =IFERROR(R102*'Fee Schedule'!$I$5,0) -> 1379.2738 | T102: =ROUND(R102-S102,2) -> 53791.68 | U102: =IFERROR(VLOOKUP(A102,Overrides!$A:$C,3,FALSE),T102) -> 53791.68 | V102: =IF(U102=T102,"","OVERRIDE") | W102: =LEFT(A102,3)&"-"&E102 -> 000-2026-11 | X102: =COUNTIFS(Positions!$A:$A,A102) -> 2 | Y102: =SUM($U$19:U102) -> 7616098.4 | Z102: =UPPER(TRIM(INDEX('Entity Map'!$E:$E,MATCH(A102,'Entity Map'!$A:$A,0)))) -> FIXED INCOME | AA102: =SUMIFS(Positions!$F:$F,Positions!$E:$E,Z102) -> 2.496646e+09 | AB102: =IFERROR(F102/AA102,0) -> 0.010044557 | AC102: =SUMPRODUCT(Positions!$F$18:$F$185,--(Positions!$A$18:$A$185=A102)) -> 50155407 | AD102: =IF(U102>40000,"A",IF(U102>8000,"B","C")) -> A | AE102: =COUNTIF('Entity Map'!$A:$A,A102) -> 1 | AF102: =MAX(Positions!$C:$C) -> 46354 | AG102: =YEAR(D102) -> 2026 | AH102: =ROUND(F102*$B$14/10000,2) -> 65202.03 | AI102: =AH102-T102 -> 11410.35 | AJ102: =AI102*$B$15 -> 11068.039 | AK102: =CONCATENATE(A102," / ",TEXT(AJ102,"0.00")) -> 00084 / 11068.04
A104: TOTAL | M104: =SUM(M19:M102) -> 8230033.3 | P104: =SUM(P19:P102) -> 8123322.6 | T104: =SUM(T19:T102) -> 7921035.8 | U104: =SUM(U19:U102) -> 7616098.4

Sheet Overrides
A1: Client | B1: Calc'd fee | C1: Agreed fee (GBP) | D1: Reason | E1: Agreed on | F1: Agreed by
A2: 00007 | B2: =INDEX(Working!$T:$T,MATCH($A2,Working!$A:$A,0)) -> 62340.34 | C2: 0 | D2: Fee waived for Q4 pending the mandate transfer agreed with the client in September. | E2: 46283 | F2: Billing Operations
A3: 00041 | B3: =INDEX(Working!$T:$T,MATCH($A3,Working!$A:$A,0)) -> 172430.45 | C3: 18500 | D3: Capped at the 2025 level; the uplift was not communicated before the billing run. | E3: 46297 | F3: Billing Operations
A4: 00062 | B4: =INDEX(Working!$T:$T,MATCH($A4,Working!$A:$A,0)) -> 92887.3 | C4: 4220.75 | D4: Manual correction: two accounts were double-counted in the position extract. | E4: 46329 | F4: Billing Operations

Sheet Allocation
A1: client_code | B1: legal_entity | C1: cost_centre | D1: period | E1: fee_gbp
A2: 00001 | B2: LuxCo | C2: CC-100 | D2: 2026-11 | E2: =SUMIFS(Working!$U:$U,Working!$A:$A,$A2) -> 22501.03
A3: 00004 | B3: LuxCo | C3: CC-130 | D3: 2026-11 | E3: =SUMIFS(Working!$U:$U,Working!$A:$A,$A3) -> 731.25
A4: 00007 | B4: LuxCo | C4: CC-100 | D4: 2026-11 | E4: =SUMIFS(Working!$U:$U,Working!$A:$A,$A4) -> 62340.34
A5: 00010 | B5: LuxCo | C5: CC-130 | D5: 2026-11 | E5: =SUMIFS(Working!$U:$U,Working!$A:$A,$A5) -> 98960.79
A6: 00013 | B6: LuxCo | C6: CC-100 | D6: 2026-11 | E6: =SUMIFS(Working!$U:$U,Working!$A:$A,$A6) -> 36673.07
A7: 00016 | B7: LuxCo | C7: CC-130 | D7: 2026-11 | E7: =SUMIFS(Working!$U:$U,Working!$A:$A,$A7) -> 200226.77
A8: 00019 | B8: LuxCo | C8: CC-100 | D8: 2026-11 | E8: =SUMIFS(Working!$U:$U,Working!$A:$A,$A8) -> 68842.27
A9: 00022 | B9: LuxCo | C9: CC-130 | D9: 2026-11 | E9: =SUMIFS(Working!$U:$U,Working!$A:$A,$A9) -> 93487.51
A10: 00025 | B10: LuxCo | C10: CC-100 | D10: 2026-11 | E10: =SUMIFS(Working!$U:$U,Working!$A:$A,$A10) -> 61513.2
A11: 00028 | B11: LuxCo | C11: CC-130 | D11: 2026-11 | E11: =SUMIFS(Working!$U:$U,Working!$A:$A,$A11) -> 731.25
A12: 00031 | B12: LuxCo | C12: CC-100 | D12: 2026-11 | E12: =SUMIFS(Working!$U:$U,Working!$A:$A,$A12) -> 150539.44
A13: 00034 | B13: LuxCo | C13: CC-130 | D13: 2026-11 | E13: =SUMIFS(Working!$U:$U,Working!$A:$A,$A13) -> 38800.28
... A29: 00082 | B29: LuxCo | C29: CC-130 | D29: 2026-11 | E29: =SUMIFS(Working!$U:$U,Working!$A:$A,$A29) -> 61815.46
B30: LuxCo subtotal | E30: =SUBTOTAL(9,E2:E29) -> 2449100.3
A31: 00002 | B31: UKCo | C31: CC-110 | D31: 2026-11 | E31: =SUMIFS(Working!$U:$U,Working!$A:$A,$A31) -> 96228.81
A32: 00005 | B32: UKCo | C32: CC-140 | D32: 2026-11 | E32: =SUMIFS(Working!$U:$U,Working!$A:$A,$A32) -> 96176.95
A33: 00008 | B33: UKCo | C33: CC-110 | D33: 2026-11 | E33: =SUMIFS(Working!$U:$U,Working!$A:$A,$A33) -> 79741.33
A34: 00011 | B34: UKCo | C34: CC-140 | D34: 2026-11 | E34: =SUMIFS(Working!$U:$U,Working!$A:$A,$A34) -> 34393.04
A35: 00014 | B35: UKCo | C35: CC-110 | D35: 2026-11 | E35: =SUMIFS(Working!$U:$U,Working!$A:$A,$A35) -> 43813.28
A36: 00017 | B36: UKCo | C36: CC-140 | D36: 2026-11 | E36: =SUMIFS(Working!$U:$U,Working!$A:$A,$A36) -> 19330.6
A37: 00020 | B37: UKCo | C37: CC-110 | D37: 2026-11 | E37: =SUMIFS(Working!$U:$U,Working!$A:$A,$A37) -> 155130.42
A38: 00023 | B38: UKCo | C38: CC-140 | D38: 2026-11 | E38: =SUMIFS(Working!$U:$U,Working!$A:$A,$A38) -> 93988.77
A39: 00026 | B39: UKCo | C39: CC-110 | D39: 2026-11 | E39: =SUMIFS(Working!$U:$U,Working!$A:$A,$A39) -> 205996.2
A40: 00029 | B40: UKCo | C40: CC-140 | D40: 2026-11 | E40: =SUMIFS(Working!$U:$U,Working!$A:$A,$A40) -> 138822.86
A41: 00032 | B41: UKCo | C41: CC-110 | D41: 2026-11 | E41: =SUMIFS(Working!$U:$U,Working!$A:$A,$A41) -> 91707.8
A42: 00035 | B42: UKCo | C42: CC-140 | D42: 2026-11 | E42: =SUMIFS(Working!$U:$U,Working!$A:$A,$A42) -> 132373.42
... A58: 00083 | B58: UKCo | C58: CC-140 | D58: 2026-11 | E58: =SUMIFS(Working!$U:$U,Working!$A:$A,$A58) -> 100184.31
B59: UKCo subtotal | E59: =SUBTOTAL(9,E31:E58) -> 2843188.1
A60: 00003 | B60: DubCo | C60: CC-120 | D60: 2026-11 | E60: =SUMIFS(Working!$U:$U,Working!$A:$A,$A60) -> 84347.46
A61: 00006 | B61: DubCo | C61: CC-150 | D61: 2026-11 | E61: =SUMIFS(Working!$U:$U,Working!$A:$A,$A61) -> 99011.38
A62: 00009 | B62: DubCo | C62: CC-120 | D62: 2026-11 | E62: =SUMIFS(Working!$U:$U,Working!$A:$A,$A62) -> 102817.11
A63: 00012 | B63: DubCo | C63: CC-150 | D63: 2026-11 | E63: =SUMIFS(Working!$U:$U,Working!$A:$A,$A63) -> 35785.22
A64: 00015 | B64: DubCo | C64: CC-120 | D64: 2026-11 | E64: =SUMIFS(Working!$U:$U,Working!$A:$A,$A64) -> 88456.55
A65: 00018 | B65: DubCo | C65: CC-150 | D65: 2026-11 | E65: =SUMIFS(Working!$U:$U,Working!$A:$A,$A65) -> 93555.79
A66: 00021 | B66: DubCo | C66: CC-120 | D66: 2026-11 | E66: =SUMIFS(Working!$U:$U,Working!$A:$A,$A66) -> 176066.19
A67: 00024 | B67: DubCo | C67: CC-150 | D67: 2026-11 | E67: =SUMIFS(Working!$U:$U,Working!$A:$A,$A67) -> 98329.2
A68: 00027 | B68: DubCo | C68: CC-120 | D68: 2026-11 | E68: =SUMIFS(Working!$U:$U,Working!$A:$A,$A68) -> 75532.16
A69: 00030 | B69: DubCo | C69: CC-150 | D69: 2026-11 | E69: =SUMIFS(Working!$U:$U,Working!$A:$A,$A69) -> 93369.64
A70: 00033 | B70: DubCo | C70: CC-120 | D70: 2026-11 | E70: =SUMIFS(Working!$U:$U,Working!$A:$A,$A70) -> 122629.26
...

Sheet Summary
A1: Fee summary by legal entity and cost centre -- November 2026
A3: Sum of fee_gbp | B3: Column Labels
A4: Row Labels | B4: 2026-11 | C4: (blank) | D4: Grand Total
A5: DubCo | B5: 2628747.3 | D5: 2628747.3
A6: CC-120 | B6: 1381038.9 | D6: 1381038.9
A7: CC-150 | B7: 1247708.4 | D7: 1247708.4
A8: DubCo subtotal | C8: 2628747.3 | D8: 2628747.3
A9: (blank) | C9: 2628747.3 | D9: 2628747.3
A10: LuxCo | B10: 2449100.3 | D10: 2449100.3
A11: CC-100 | B11: 1188410.7 | D11: 1188410.7
A12: CC-130 | B12: 1260689.6 | D12: 1260689.6
A13: LuxCo subtotal | C13: 2449100.3 | D13: 2449100.3
A14: (blank) | C14: 2449100.3 | D14: 2449100.3
A15: UKCo | B15: 2843188.1 | D15: 2843188.1
A16: CC-110 | B16: 1471800.8 | D16: 1471800.8
A17: CC-140 | B17: 1371387.3 | D17: 1371387.3
A18: UKCo subtotal | C18: 2843188.1 | D18: 2843188.1
A19: (blank) | C19: 2843188.1 | D19: 2843188.1
A20: Grand Total | B20: 7921035.8 | C20: 7921035.8 | D20: 15842072

Sheet Post
A1: Run these against the ledger once the fee run is approved.
A3: SQL to run
A4: ="INSERT INTO fin.fee_invoice (client_code, client_name, period_month, fee_gbp) VALUES ('"&Working!$A19&"', '"&'Entity Map'!$B2&"', '"&Working!$E19&"', "&Working!$U19&");" -> INSERT INTO fin.fee_invoice (client_code, client_name, period_month, fee_gbp) VALUES ('00001', 'Client 001 Holdings', '2026-11', 22501.03);
A5: ="INSERT INTO fin.fee_invoice (client_code, client_name, period_month, fee_gbp) VALUES ('"&Working!$A20&"', '"&'Entity Map'!$B3&"', '"&Working!$E20&"', "&Working!$U20&");" -> INSERT INTO fin.fee_invoice (client_code, client_name, period_month, fee_gbp) VALUES ('00002', 'Client 002 Holdings', '2026-11', 96228.81);
A6: ="INSERT INTO fin.fee_invoice (client_code, client_name, period_month, fee_gbp) VALUES ('"&Working!$A21&"', '"&'Entity Map'!$B4&"', '"&Working!$E21&"', "&Working!$U21&");" -> INSERT INTO fin.fee_invoice (client_code, client_name, period_month, fee_gbp) VALUES ('00003', 'Client 003 Holdings', '2026-11', 84347.46);
A7: ="INSERT INTO fin.fee_invoice (client_code, client_name, period_month, fee_gbp) VALUES ('"&Working!$A22&"', '"&'Entity Map'!$B5&"', '"&Working!$E22&"', "&Working!$U22&");" -> INSERT INTO fin.fee_invoice (client_code, client_name, period_month, fee_gbp) VALUES ('00004', 'Client 004 Holdings', '2026-11', 731.25);
A8: ="INSERT INTO fin.fee_invoice (client_code, client_name, period_month, fee_gbp) VALUES ('"&Working!$A23&"', '"&'Entity Map'!$B6&"', '"&Working!$E23&"', "&Working!$U23&");" -> INSERT INTO fin.fee_invoice (client_code, client_name, period_month, fee_gbp) VALUES ('00005', 'Client 005 Holdings', '2026-11', 96176.95);
A9: ="INSERT INTO fin.fee_invoice (client_code, client_name, period_month, fee_gbp) VALUES ('"&Working!$A24&"', '"&'Entity Map'!$B7&"', '"&Working!$E24&"', "&Working!$U24&");" -> INSERT INTO fin.fee_invoice (client_code, client_name, period_month, fee_gbp) VALUES ('00006', 'Client 006 Holdings', '2026-11', 99011.38);
A10: ="INSERT INTO fin.fee_invoice (client_code, client_name, period_month, fee_gbp) VALUES ('"&Working!$A25&"', '"&'Entity Map'!$B8&"', '"&Working!$E25&"', "&Working!$U25&");" -> INSERT INTO fin.fee_invoice (client_code, client_name, period_month, fee_gbp) VALUES ('00007', 'Client 007 Holdings', '2026-11', 0);
A11: ="INSERT INTO fin.fee_invoice (client_code, client_name, period_month, fee_gbp) VALUES ('"&Working!$A26&"', '"&'Entity Map'!$B9&"', '"&Working!$E26&"', "&Working!$U26&");" -> INSERT INTO fin.fee_invoice (client_code, client_name, period_month, fee_gbp) VALUES ('00008', 'Client 008 Holdings', '2026-11', 79741.33);
A12: ="INSERT INTO fin.fee_invoice (client_code, client_name, period_month, fee_gbp) VALUES ('"&Working!$A27&"', '"&'Entity Map'!$B10&"', '"&Working!$E27&"', "&Working!$U27&");" -> INSERT INTO fin.fee_invoice (client_code, client_name, period_month, fee_gbp) VALUES ('00009', 'Client 009 Holdings', '2026-11', 102817.11);
A13: ="INSERT INTO fin.fee_invoice (client_code, client_name, period_month, fee_gbp) VALUES ('"&Working!$A28&"', '"&'Entity Map'!$B11&"', '"&Working!$E28&"', "&Working!$U28&");" -> INSERT INTO fin.fee_invoice (client_code, client_name, period_month, fee_gbp) VALUES ('00010', 'Client 010 Holdings', '2026-11', 98960.79);
A14: ="INSERT INTO fin.fee_invoice (client_code, client_name, period_month, fee_gbp) VALUES ('"&Working!$A29&"', '"&'Entity Map'!$B12&"', '"&Working!$E29&"', "&Working!$U29&");" -> INSERT INTO fin.fee_invoice (client_code, client_name, period_month, fee_gbp) VALUES ('00011', 'Client 011 Holdings', '2026-11', 34393.04);
A15: ="INSERT INTO fin.fee_invoice (client_code, client_name, period_month, fee_gbp) VALUES ('"&Working!$A30&"', '"&'Entity Map'!$B13&"', '"&Working!$E30&"', "&Working!$U30&");" -> INSERT INTO fin.fee_invoice (client_code, client_name, period_month, fee_gbp) VALUES ('00012', 'Client 012 Holdings', '2026-11', 35785.22);
... A87: ="INSERT INTO fin.fee_invoice (client_code, client_name, period_month, fee_gbp) VALUES ('"&Working!$A102&"', '"&'Entity Map'!$B85&"', '"&Working!$E102&"', "&Working!$U102&");" -> INSERT INTO fin.fee_invoice (client_code, client_name, period_month, fee_gbp) VALUES ('00084', 'Client 084 Holdings', '2026-11', 53791.68);

Sheet Entity Map
A1: client_code | B1: client_name | C1: legal_entity | D1: cost_centre | E1: mandate | F1: onboarded
A2: 00001 | B2: Client 001 Holdings | C2: LuxCo | D2: CC-100 | E2: balanced | F2: 45352
A3: 00002 | B3: Client 002 Holdings | C3: UKCo | D3: CC-110 | E3: equity | F3: 45353
A4: 00003 | B4: Client 003 Holdings | C4: DubCo | D4: CC-120 | E4: fixed income | F4: 45354
A5: 00004 | B5: Client 004 Holdings | C5: LuxCo | D5: CC-130 | E5: balanced | F5: 45355
A6: 00005 | B6: Client 005 Holdings | C6: UKCo | D6: CC-140 | E6: equity | F6: 45356
A7: 00006 | B7: Client 006 Holdings | C7: DubCo | D7: CC-150 | E7: fixed income | F7: 45357
A8: 00007 | B8: Client 007 Holdings | C8: LuxCo | D8: CC-100 | E8: balanced | F8: 45358
A9: 00008 | B9: Client 008 Holdings | C9: UKCo | D9: CC-110 | E9: equity | F9: 45359
A10: 00009 | B10: Client 009 Holdings | C10: DubCo | D10: CC-120 | E10: fixed income | F10: 45360
A11: 00010 | B11: Client 010 Holdings | C11: LuxCo | D11: CC-130 | E11: balanced | F11: 45361
A12: 00011 | B12: Client 011 Holdings | C12: UKCo | D12: CC-140 | E12: equity | F12: 45362
A13: 00012 | B13: Client 012 Holdings | C13: DubCo | D13: CC-150 | E13: fixed income | F13: 45363
... A85: 00084 | B85: Client 084 Holdings | C85: DubCo | D85: CC-150 | E85: fixed income | F85: 45354

Sheet Recon
A1: Entity | B1: Oct-26 (GBP) | C1: Nov-26 (GBP) | D1: Var (GBP) | E1: Commentary | F1: Var % | G1: Flag
A2: LuxCo | B2: 412880.44 | C2: =SUMIF(Allocation!$B:$B,$A2,Allocation!$E:$E) -> 2449100.3 | D2: =C2-B2 -> 2036219.9 | E2: Transfer in from the Geneva book; expected. | F2: =IFERROR(D2/B2,0) -> 4.9317422 | G2: =IF(ABS(F2)>0.05,"REVIEW","") -> REVIEW
A3: UKCo | B3: 388100.02 | C3: =SUMIF(Allocation!$B:$B,$A3,Allocation!$E:$E) -> 2843188.1 | D3: =C3-B3 -> 2455088.1 | E3: Two mandates closed in October. | F3: =IFERROR(D3/B3,0) -> 6.3259159 | G3: =IF(ABS(F3)>0.05,"REVIEW","") -> REVIEW
A4: DubCo | B4: 205990.18 | C4: =SUMIF(Allocation!$B:$B,$A4,Allocation!$E:$E) -> 2628747.3 | D4: =C4-B4 -> 2422757.1 | E4: Unexplained. Raised with the desk 2026-11-04. | F4: =IFERROR(D4/B4,0) -> 11.761518 | G4: =IF(ABS(F4)>0.05,"REVIEW","") -> REVIEW

Sheet Sign-off
A1: Management fee billing run -- sign-off
A3: Purpose
A4: Calculate the management fee owed by each client for the month, apply the agreed floors, caps and discounts, allocate the result to the legal entity and cost centre that will carry it, and post the invoices to the ledger.
A6: Background
A7: The tiered schedule replaced a flat 26bps rate in January 2024. The old columns are still in the Working tab because the 2024 comparatives were needed for the audit; nothing reads them now.
A9: Known issues
A10: The Allocation tab is left on manual calculation because recalculating it over a full extract takes several minutes, so its figures are from before the overrides were agreed and do not match the Working tab. Recalculate before relying on them. Three clients have agreed fees that override the calculation -- see the Overrides tab, and confirm each one still applies before posting.
A12: Cadence
A13: Monthly, on the third working day, after the position extract has been signed off by Middle Office.
